# Error Handling with Camel

-	Camel is used to integrate with different systems
-	Integrating systems over n/w has its own challenges
	
	-	N/w could be down
	-	n/w would be slow
	-	Request may fail for no reason
	
	
## Different ways of Handling errors in Camel

-	Recoverable errors
-	Irrecoverable errors

	
	-	Recoverable Errors
	
		-	Scheduled Maintenance
		-	Some Temporary N/w Issues
		
	-	Irrecoverable Errors
	
		-	Try to connect to DB that doesn't exist
		-	Try to access wrong service or host
		-	Trying to access wrong server
		-	Trying to make an API call to REST endpoints that doesn't even exist
		
	
	
## 	Camel Error Handling

-	Camel Error Handling is part of camel core library
-	When ever an exception occurred in the route camel will populate the exception with actual exception
-	Exception will throw back to from() route and will not reaches the to() route
-	Recoverable and Irrecoverable exception can be accessible from Camel Exchange

## Default Error Handling - Approach 1

-	errorHandler(defaultErrorHandler()) 

	-	Is the basic way of handling the handler
	-	Will gets executed for all types of Exception
	-	Can try to redelivery using redelivery mechanism
	-	Disadvantage of default errorHanlder() is that, it doesn't support to handle different types of exception
	
	Code Snippet:
	
		public class DefaultErrorHandlingRoute extends RouteBuilder {

			@Override
			public void configure() throws Exception {

				errorHandler(defaultErrorHandler()
						.maximumRedeliveries(2)
						.redeliveryDelay(5000)
						.backOffMultiplier(2)
						.retryAttemptedLogLevel(LoggingLevel.WARN));

				from("direct:exception").to("log:?level=INFO&showAll=true&multiline=true").bean(new DataTransformer())
						.to("log:?level=INFO&showAll=true&multiline=true").to("mock:errorQueue");
			}
		}
	
		public class DataTransformer {

			public String transform(String input) {

				try {
					input = input.replaceAll(",", "|");
				} catch (RuntimeException r) {
					throw r;
				} catch (Exception e) {
					throw e;
				}
				return input;
			}
		}

		public class DefaultErrorHandlingRouteTest extends CamelTestSupport {
			public RouteBuilder createRouteBuilder() {
				return new DefaultErrorHandlingRoute();
			}

			@Test()
			public void testDefaultErrorHandling() throws InterruptedException {
				String input = null, expected = "";
				String actual =  template.requestBody("direct:exception",input, String.class);
				assertEquals(expected,actual);
			}
		}

## OnException Handling - Approach 2

-	OnException support handling errors based on the exception types
-	Using OnException approach we can format the exception and send it back to client or kafka topic or jms queue
-	We can access the exception and customize the exception by getting the exception property from message
-	handled(true): is used to say the camel that we are handling it explicitly
-	process(new GenerateErrorResponseProcessor()): is used to process and customize the exception and send meaningfull details to caller
-	to("kafka:errortopic"): is used to send the error to kafka topic
-	log(LoggingLevel.WARN, "Exception in Processor caught here") : is used to log the error in different level
-	continued(true): Used to tell camel to ignore the error and continue to send the Exchange to next route
	-	We cant use both continued(true) and handled(true) in same routes

	
	Code Snippet:
	
		
		public class OnExceptionHandlerRoute extends RouteBuilder {

			public void configure() throws Exception {

				 //onException(RuntimeException.class).log(LoggingLevel.WARN, "Exception in Bean caught here");

				//onException(ApplicationException.class).log(LoggingLevel.WARN, "Application Exception in Bean caught here");

				//Multiple Exceptions in same line
				//onException(ApplicationException.class).log(LoggingLevel.WARN, "Application Exception in Bean caught here");

				//  onException(SQLException.class).log(LoggingLevel.WARN, "Exception while connecting to DB");*/

				//With Re-delivery and redleivery delay
			   // onException(RuntimeException.class,ApplicationException.class).maximumRedeliveries(2).redeliveryDelay(5000).log(LoggingLevel.WARN, "Exception in Processor caught here");

				//with Redelivery and Handled
			   // onException(RuntimeException.class,ApplicationException.class).handled(true).maximumRedeliveries(2).delay(2000).process(new GenerateErrorResponseProcessor()).log(LoggingLevel.WARN, "Exception in Processor caught here");
				// onException(RuntimeException.class,ApplicationException.class).handled(true).maximumRedeliveries(2).delay(2000).process(new GenerateErrorResponseProcessor()).to("kafka:errortopic").log(LoggingLevel.WARN, "Exception in Processor caught here");

				//Ignoring Exception:
				//You cant use continued and handled in the same route.
				onException(RuntimeException.class,ApplicationException.class).continued(true).log(LoggingLevel.WARN, "Exception in Processor caught here");

				from("direct:exception")
						.bean(new DataModifier(), "mapOnException")
						.to("log:?level=INFO&showBody=true");
			}
		}
		
		public class GenerateErrorResponseProcessor  implements Processor {

			public void process(Exchange exchange) throws Exception {

				Exception e = exchange.getProperty(Exchange.EXCEPTION_CAUGHT, Exception.class);
				System.out.println("Acutal Exceptipn Message "  + e.getMessage());
				System.out.println("Acutal Exceptipn Class "  + e.getClass());

				String failedEndoint = (String) exchange.getProperty(Exchange.FAILURE_ENDPOINT);
				System.out.println("Failed Endpoint : " + failedEndoint);


				exchange.getIn().setBody("Exception happened in the route.");
			}
		}

		
		
		public class DataModifier {

			Logger log = Logger.getLogger(DataModifier.class.getName());

			public String map(String input) throws Exception {
				String newBody=null;
				try{
					 newBody = input.replace(",", "*");
				}catch(RuntimeException e){
					log.severe("RuntimeException : " + e);
					//throw e;
				}
				catch(Exception e){
					log.severe("Exception : " + e);
					throw e;
				}
				return  newBody;

			}

			public String mapOnException(String input) throws Exception {

				String newBody=null;
				try{
					newBody = input.replace(",", "*");
				}catch(RuntimeException e){
					log.severe("RuntimeException : " + e);
					//throw e;
					throw new ApplicationException(e.getMessage());
				}
				catch(Exception e){
					log.severe("Exception : " + e);
					throw e;
				}
				return  newBody;
			}
		}

		
		public class OnExceptionHandlerRouteTest extends CamelTestSupport {

			@Override
			protected RouteBuilder createRouteBuilder() throws Exception {
				return new OnExceptionHandlerRoute();
			}

			
			// 1st Scenario we got the exception
			@Test(expected = RuntimeException.class)
			public void exceptionCheck_nohandled(){

				String request=null;
				final String response = template.requestBody("direct:exception", request, String.class);
				System.out.println("Response is  : " + response);

			}

			// 2nd Scenario we handled the exception with processor and customized it
			@Test
			public void exceptionCheck_handled_in_processor(){

				String request=null;
				String expected ="Exception happened in the route.";
				final String response = template.requestBody("direct:exception", request, String.class);
				System.out.println("Response is  : " + response);
				assertEquals(expected, response);
			}

			
			// 3rd Scenario we ignored the exception and continued to process the route
			@Test
			public void exceptionCheck_continue(){

				String request=null;
				String expected =null;
				final String response = template.requestBody("direct:exception", request, String.class);
				System.out.println("Response is  : " + response);
				assertEquals(expected, response);
			}


		}

	


























		